Workbook

Sheet Sheet1
A1: sku | B1: qty_available | C1: min_order_qty | D1: name | E1: upc | F1: product_id | G1: image_url | H1: material | I1: dimensions | J1: color | K1: min_case_price | L1: min_case_qty | M1: case_price | N1: case_qty | O1: bullet_1 | P1: bullet_2 | Q1: bullet_3 | R1: bullet_4 | S1: bullet_5 | T1: bullet_6 | U1: bullet_7 | V1: bullet_8 | W1: bullet_9 | X1: bullet_10 | Y1: bullet_11 | Z1: bullet_12 | AA1: bullet_13 | AB1: bullet_14 | AC1: bullet_15 | AD1: bullet_16
A2: G3216179 | B2: 2232 | C2: 6 | D2: 4' Red Ball Garland | E2: 048893851880 | F2: 109721 | G2: https://www.razimports.com/media/catalog_product/ImagesFiles2/G3216179.jpg?quality=100&bg-color=255,255,255&fit=bounds&height=1000&width=1000&canvas=1000:1000 | H2: Made of PLASTIC | I2: Measures: 4' L | J2: RED | K2: 14.25 | L2: (6EA) Min. | M2: 12.60 | N2: (12EA) Case
A3: 3911406 | B3: 2082 | C3: 2 | D3: 24" Church Lighted Print | E3: 048893073978 | F3: 92654 | G3: https://www.razimports.com/media/catalog_product/ImagesFiles2/3911406.jpg?quality=100&bg-color=255,255,255&fit=bounds&height=1000&width=1000&canvas=1000:1000 | H3: Made of POLYESTER CANVAS | I3: Measures: 24" L x 1" W x 18" H | J3: MULTICOLOR | K3: 31.40 | L3: (2EA) Min. | M3: 27.70 | N3: (8EA) Case | O3: REQUIRES 3 AA BATTERIES | P3: 6 HOUR TIMER REPEATS EVERY 18 HOURS | Q3: CORNER BUTTON ACTIVATED | R3: Artist: © Galaxy of Graphics Licensing LLC, Sall
A4: G3416336 | B4: 1920 | C4: 6 | D4: 4' Multicolor Ball Garland | E4: 048893987831 | F4: 109724 | G4: https://www.razimports.com/media/catalog_product/ImagesFiles2/G3416336.jpg?quality=100&bg-color=255,255,255&fit=bounds&height=1000&width=1000&canvas=1000:1000 | H4: Made of PLASTIC | I4: Measures: 4' L | J4: MULTICOLOR | K4: 14.90 | L4: (6EA) Min. | M4: 13.20 | N4: (12EA) Case
A5: 4559488 | B5: 1592 | C5: 8 | D5: 10.5" Gold Tree Taper Candles | E5: 048893931223 | F5: 104945 | G5: https://www.razimports.com/media/catalog_product/ImagesFiles2/4559488.jpg?quality=100&bg-color=255,255,255&fit=bounds&height=1000&width=1000&canvas=1000:1000 | H5: Made of WAX | I5: Measures: 1.75"D x 10.5"H | J5: SET OF 2 GOLD - YELLOW | K5: 16.00 | L5: (8SET) Min. | M5: 14.40 | N5: (16SET) Case | O5: REQUIRES 2 AAA BATTERIES EACH | P5: 6 HOUR TIMER REPEATS EVERY 18 HOURS | Q5: BATTERY LIFE APPROX 120 HOURS
A6: 4533532 | B6: 1536 | C6: 24 | D6: 4" Clear Seamless Iridescent Ball | E6: 048893931292 | F6: 102740 | G6: https://www.razimports.com/media/catalog_product/ImagesFiles2/4533532.jpg?quality=100&bg-color=255,255,255&fit=bounds&height=1000&width=1000&canvas=1000:1000 | H6: Made of PET (POLYETHYLENE TEREPHTHALATE) | I6: Measures: 4" D | J6: CLEAR | K6: 2.75 | L6: (24EA) Min. | M6: 2.45 | N6: (48EA) Case
A7: 4124532 | B7: 1212 | C7: 24 | D7: *SB* 5" Local Grown Christmas Trees Ball Ornament | E7: 048893212469 | F7: 93086 | G7: https://www.razimports.com/media/catalog_product/ImagesFiles2/4124532.jpg?quality=100&bg-color=255,255,255&fit=bounds&height=1000&width=1000&canvas=1000:1000 | H7: Made of GLASS | I7: Measures: 5" D | J7: WHITE | K7: 7.00 | L7: (6EA) Minimum | M7: 3.60 | N7: (24EA) | O7: Artist: © Nicole Tamarin
A8: 4432922 | B8: 1200 | C8: 8 | D8: 10.5" Ivory Tree Taper Candles | E8: 048893490805 | F8: 96116 | G8: https://www.razimports.com/media/catalog_product/ImagesFiles2/4432922.jpg?quality=100&bg-color=255,255,255&fit=bounds&height=1000&width=1000&canvas=1000:1000 | H8: Made of WAX | I8: Measures: 1.75"D x 10.5"H | J8: SET OF 2 WHITE - IVORY | K8: 15.45 | L8: (8SET) Min. | M8: 13.85 | N8: (16SET) Case | O8: REQUIRES 2 AAA BATTERIES EACH | P8: 6 HOUR TIMER REPEATS EVERY 18 HOURS | Q8: INDOOR USE ONLY | R8: LIGHTS APPROX 20,000 HOURS
A9: 4324035 | B9: 1180 | C9: 10 | D9: 6" Clip-On Lighted Candles with Remote | E9: 048893546533 | F9: 94448 | G9: https://www.razimports.com/media/catalog_product/ImagesFiles2/4324035.jpg?quality=100&bg-color=255,255,255&fit=bounds&height=1000&width=1000&canvas=1000:1000 | H9: Made of PLASTIC | I9: Measures: 1.5"L x 0.5"W x 7"H | J9: BOX OF 10 WHITE | K9: 20.75 | L9: (10BOX) Min. | M9: 18.55 | N9: (20BOX) Case | O9: EACH CANDLE REQUIRES 1 AAA BATTERY | P9: 6 HOUR TIMER REPEATS EVERY 18 HOURS | Q9: INCLUDES REMOTE WITH CR2025 BATTERY | R9: INDOOR USE ONLY | S9: LIGHTS APPROX 12,000 HOURS
A10: F4517615 | B10: 1140 | C10: 12 | D10: 32" Pearl and Crystal Dripping Spray | E10: 048893937966 | F10: 108620 | G10: https://www.razimports.com/media/catalog_product/ImagesFiles2/F4517615.jpg?quality=100&bg-color=255,255,255&fit=bounds&height=1000&width=1000&canvas=1000:1000 | H10: Made of PLASTIC | I10: Measures: 32" L | J10: GOLD | K10: 8.70 | L10: (12EA) Min. | M10: 7.25 | N10: (36EA) Case
A11: G4516359 | B11: 1104 | C11: 12 | D11: 6' Pearl Garland | E11: 048893425883 | F11: 110099 | G11: https://www.razimports.com/media/catalog_product/ImagesFiles2/G4516359.jpg?quality=100&bg-color=255,255,255&fit=bounds&height=1000&width=1000&canvas=1000:1000 | H11: Made of PLASTIC | I11: Measures: 6' L | J11: WHITE - PEARL | K11: 10.35 | L11: (12EA) Min. | M11: 8.95 | N11: (24EA) Case
A12: G4416416 | B12: 1080 | C12: 12 | D12: 15' x 0.5" Red Beaded Garland | E12: 048893986865 | F12: 109952 | G12: https://www.razimports.com/media/catalog_product/ImagesFiles2/G4416416.jpg?quality=100&bg-color=255,255,255&fit=bounds&height=1000&width=1000&canvas=1000:1000 | H12: Made of PLASTIC | I12: Measures: 15' L | J12: RED | K12: 6.30 | L12: (12EA) Min. | M12: 5.30 | N12: (48EA) Case | O12: 0.5" GIRTH | P12: Catalog (Christmas 2025) on page 27
A13: G4516540 | B13: 1056 | C13: 12 | D13: 15' X 0.5" Blue Beaded Garland | E13: 048893425814 | F13: 110114 | G13: https://www.razimports.com/media/catalog_product/ImagesFiles2/G4516540.jpg?quality=100&bg-color=255,255,255&fit=bounds&height=1000&width=1000&canvas=1000:1000 | H13: Made of PLASTIC | I13: Measures: 15' L | J13: BLUE | K13: 6.30 | L13: (12EA) Min. | M13: 5.30 | N13: (48EA) Case | O13: 0.5" GIRTH
A14: G3526011 | B14: 1044 | C14: 12 | D14: 15' x 0.5" Gold Beaded Garland | E14: 048893673635 | F14: 109730 | G14: https://www.razimports.com/media/catalog_product/ImagesFiles2/G3526011.jpg?quality=100&bg-color=255,255,255&fit=bounds&height=1000&width=1000&canvas=1000:1000 | H14: Made of PLASTIC | I14: Measures: 15' L | J14: GOLD - CHAMPAGNE | K14: 6.30 | L14: (12EA) Min. | M14: 5.30 | N14: (48EA) Case | O14: 0.5" GIRTH | P14: Catalog (Christmas 2025) on page 131
A15: 4324047 | B15: 1008 | C15: 12 | D15: *SB* 2" X 4" Red Glass Ivory Pillar Candle | E15: 048893531133 | F15: 94463 | G15: https://www.razimports.com/media/catalog_product/ImagesFiles2/4324047.jpg?quality=100&bg-color=255,255,255&fit=bounds&height=1000&width=1000&canvas=1000:1000 | H15: Made of PLASTIC | I15: Measures: 2" D x 4" H | J15: RED | K15: 5.50 | L15: (12EA) Minimum | M15: 3.00 | N15: (12EA) | O15: REQUIRES 2 AA BATTERIES | P15: 6 HOUR TIMER REPEATS EVERY 18 HOURS | Q15: BATTERY LIFE APPROX 160 HOURS | R15: REMOTE READY | S15: CAN BE USED WITH REMOTE #X4324020
A16: F4542099 | B16: 996 | C16: 12 | D16: 24" Champagne and Pearl Spray | E16: 048893936976 | F16: 109043 | G16: https://www.razimports.com/media/catalog_product/ImagesFiles2/F4542099.jpg?quality=100&bg-color=255,255,255&fit=bounds&height=1000&width=1000&canvas=1000:1000 | H16: Made of PE (POLYETHYLENE) | I16: Measures: 24" L | J16: WHITE - PEARL | K16: 5.65 | L16: (12EA) Min. | M16: 4.75 | N16: (36EA) Case | O16: Catalog (Christmas 2025) on page 293
A17: G4416225 | B17: 936 | C17: 12 | D17: 6' Pearl Garland | E17: 048893986933 | F17: 109940 | G17: https://www.razimports.com/media/catalog_product/ImagesFiles2/G4416225.jpg?quality=100&bg-color=255,255,255&fit=bounds&height=1000&width=1000&canvas=1000:1000 | H17: Made of PLASTIC | I17: Measures: 6' L | J17: IVORY | K17: 9.80 | L17: (12EA) Min. | M17: 8.50 | N17: (24EA) Case | O17: Catalog (Christmas 2025) on page 241
A18: 4432921 | B18: 912 | C18: 8 | D18: 10.5" Green Tree Taper Candles | E18: 048893490812 | F18: 96113 | G18: https://www.razimports.com/media/catalog_product/ImagesFiles2/4432921.jpg?quality=100&bg-color=255,255,255&fit=bounds&height=1000&width=1000&canvas=1000:1000 | H18: Made of WAX | I18: Measures: 1.75"D x 10.5"H | J18: SET OF 2 GREEN | K18: 15.45 | L18: (8SET) Min. | M18: 13.85 | N18: (16SET) Case | O18: REQUIRES 2 AAA BATTERIES EACH | P18: 6 HOUR TIMER REPEATS EVERY 18 HOURS | Q18: INDOOR USE ONLY | R18: LIGHTS APPROX 20,000 HOURS
A19: 4533520 | B19: 864 | C19: 24 | D19: 4" Teal Seamless Iridescent Ball | E19: 048893931421 | F19: 102704 | G19: https://www.razimports.com/media/catalog_product/ImagesFiles2/4533520.jpg?quality=100&bg-color=255,255,255&fit=bounds&height=1000&width=1000&canvas=1000:1000 | H19: Made of PET (POLYETHYLENE TEREPHTHALATE) | I19: Measures: 4" D | J19: BLUE - TEAL | K19: 2.75 | L19: (24EA) Min. | M19: 2.45 | N19: (48EA) Case | O19: Catalog (Christmas 2025) on page 439
A20: F4502264 | B20: 840 | C20: 12 | D20: 27" Holly Berry Felt Spray | E20: 048893939663 | F20: 108128 | G20: https://www.razimports.com/media/catalog_product/ImagesFiles2/F4502264.jpg?quality=100&bg-color=255,255,255&fit=bounds&height=1000&width=1000&canvas=1000:1000 | H20: Made of POLYESTER | I20: Measures: 27" L | J20: GREEN | K20: 8.10 | L20: (12EA) Min. | M20: 7.15 | N20: (24EA) Case
A21: G4517606 | B21: 840 | C21: 12 | D21: 5' Pearl and Crystal Beaded Garland | E21: 048893425678 | F21: 110138 | G21: https://www.razimports.com/media/catalog_product/ImagesFiles2/G4517606.jpg?quality=100&bg-color=255,255,255&fit=bounds&height=1000&width=1000&canvas=1000:1000 | H21: Made of PLASTIC | I21: Measures: 5' L | J21: WHITE - PEARL | K21: 8.30 | L21: (12EA) Min. | M21: 6.90 | N21: (36EA) Case
A22: 37094 | B22: 802 | C22: 8 | D22: *SB* 8" Moving Flame Red Pillar Candles With Remote, Set/3 | E22: 048893921507 | F22: 92468 | G22: https://www.razimports.com/media/catalog_product/ImagesFiles2/37094.jpg?quality=100&bg-color=255,255,255&fit=bounds&height=1000&width=1000&canvas=1000:1000 | H22: Made of WAX | I22: Measures: 3"D x 8"H; 3"D x 6"H; 3"D x 4.5"H | J22: SET OF 4 RED-CINNAMON SCENTED | K22: 64.50 | L22: (8SET) Minimum | M22: 38.70 | N22: (8SET) | O22: REQUIRES 2 C BATTERIES | P22: 5 HOUR TIMER REPEATS EVERY 19 HOURS | Q22: BATTERY LIFE APPROX 500 HOURS | R22: REMOTE READY | S22: CAN BE USED WITH REMOTE #X15997
A23: 4310135 | B23: 768 | C23: 24 | D23: 3.5" Beaded Berry Candle Ring | E23: 048893524845 | F23: 93956 | G23: https://www.razimports.com/media/catalog_product/ImagesFiles2/4310135.jpg?quality=100&bg-color=255,255,255&fit=bounds&height=1000&width=1000&canvas=1000:1000 | H23: Made of GYPSUM | I23: Measures: 3.5" D | J23: MULTICOLOR | K23: 2.65 | L23: (24EA) Min. | M23: 2.25 | N23: (144EA) Case | O23: FITS TAPER CANDLE
A24: 4533526 | B24: 768 | C24: 24 | D24: 4" Purple Seamless Iridescent Ball | E24: 048893931360 | F24: 102722 | G24: https://www.razimports.com/media/catalog_product/ImagesFiles2/4533526.jpg?quality=100&bg-color=255,255,255&fit=bounds&height=1000&width=1000&canvas=1000:1000 | H24: Made of PET (POLYETHYLENE TEREPHTHALATE) | I24: Measures: 4" D | J24: PURPLE | K24: 2.75 | L24: (24EA) Min. | M24: 2.45 | N24: (48EA) Case | O24: Catalog (Christmas 2025) on page 439
A25: 4202410 | B25: 756 | C25: 12 | D25: *SB* 9" Knit Packages with Plaid Bows | E25: 048893809348 | F25: 93317 | G25: https://www.razimports.com/media/catalog_product/ImagesFiles2/4202410.jpg?quality=100&bg-color=255,255,255&fit=bounds&height=1000&width=1000&canvas=1000:1000 | H25: Made of STYROFOAM | I25: Measures: 5.25"L x 5.25"W x 9"H; 5.25"L x 5.25"W x 6"H | J25: SET OF 2 WHITE - CREAM | K25: 17.55 | L25: (3SET) Minimum | M25: 9.15 | N25: (12SET)
A26: G4506740 | B26: 756 | C26: 12 | D26: 4' Wired Vintage Garland | E26: 048893936211 | F26: 110021 | G26: https://www.razimports.com/media/catalog_product/ImagesFiles2/G4506740.jpg?quality=100&bg-color=255,255,255&fit=bounds&height=1000&width=1000&canvas=1000:1000 | H26: Made of PLASTIC | I26: Measures: 4' L | J26: MULTICOLOR | K26: 4.95 | L26: (12EA) Min. | M26: 4.10 | N26: (48EA) Case
A27: R4571854 | B27: 750 | C27: 6 | D27: 1.5" X 10 Yds Green Satin with Red Pom Pom Edge Wired Ribbon | E27: 048893424107 | F27: 110846 | G27: https://www.razimports.com/media/catalog_product/ImagesFiles2/R4571854.jpg?quality=100&bg-color=255,255,255&fit=bounds&height=1000&width=1000&canvas=1000:1000 | H27: Made of POLYESTER | I27: Measures: 10YDS L x 1.5" W | J27: MULTICOLOR | K27: 13.70 | L27: (6EA) Min. | M27: 12.20 | N27: (12EA) Case | O27: Catalog (Christmas 2025) on page 428
A28: F4422726 | B28: 744 | C28: 12 | D28: 24" Glittered Pearl Fern Spray | E28: 048893483883 | F28: 107888 | G28: https://www.razimports.com/media/catalog_product/ImagesFiles2/F4422726.jpg?quality=100&bg-color=255,255,255&fit=bounds&height=1000&width=1000&canvas=1000:1000 | H28: Made of PE (POLYETHYLENE) | I28: Measures: 24" L | J28: NATURAL | K28: 4.80 | L28: (12EA) Min. | M28: 4.00 | N28: (48EA) Case
A29: G4516539 | B29: 744 | C29: 12 | D29: 15' X 0.5" Green Beaded Garland | E29: 048893425838 | F29: 110111 | G29: https://www.razimports.com/media/catalog_product/ImagesFiles2/G4516539.jpg?quality=100&bg-color=255,255,255&fit=bounds&height=1000&width=1000&canvas=1000:1000 | H29: Made of PLASTIC | I29: Measures: 15' L | J29: GREEN | K29: 6.30 | L29: (12EA) Min. | M29: 5.30 | N29: (48EA) Case | O29: 0.5" GIRTH
A30: 4514868 | B30: 720 | C30: 24 | D30: 4" Sprinkled Ball Ornament | E30: 048893955878 | F30: 98855 | G30: https://www.razimports.com/media/catalog_product/ImagesFiles2/4514868.jpg?quality=100&bg-color=255,255,255&fit=bounds&height=1000&width=1000&canvas=1000:1000 | H30: Made of PLASTIC | I30: Measures: 4"D | J30: 3 ASST MULTICOLOR | K30: 3.20 | L30: (24EA) Min. | M30: 2.80 | N30: (48EA) Case
A31: F4206798 | B31: 720 | C31: 48 | D31: *SB* 12" Blue Plaid Poinsettia Stem | E31: 048893974343 | F31: 107639 | G31: https://www.razimports.com/media/catalog_product/ImagesFiles2/F4206798.jpg?quality=100&bg-color=255,255,255&fit=bounds&height=1000&width=1000&canvas=1000:1000 | H31: Made of POLYESTER | I31: Measures: 10" D x 12" H | J31: BLUE - DARK | K31: 6.50 | L31: (12EA) Minimum | M31: 3.40 | N31: (48EA)
A32: 4136307 | B32: 712 | C32: 8 | D32: *SB* 20" Let It Snow Embossed Metal Framed Wall Art | E32: 048893214456 | F32: 93170 | G32: https://www.razimports.com/media/catalog_product/ImagesFiles2/4136307.jpg?quality=100&bg-color=255,255,255&fit=bounds&height=1000&width=1000&canvas=1000:1000 | H32: Made of METAL | I32: Measures: 20" L x 0.75" W x 20" H | J32: BLACK | K32: 19.50 | L32: (4EA) Minimum | M32: 10.45 | N32: (8EA) | O32: Artist: © Bex Morley
A33: 4216921 | B33: 670 | C33: 8 | D33: *SB* 11" Gnomes in Forest Lighted Water Lantern | E33: 048893384111 | F33: 93551 | G33: https://www.razimports.com/media/catalog_product/ImagesFiles2/4216921.jpg?quality=100&bg-color=255,255,255&fit=bounds&height=1000&width=1000&canvas=1000:1000 | H33: Made of PLASTIC | I33: Measures: 7" L x 3.25" W x 11" H | J33: BLACK | K33: 30.00 | L33: (4EA) Minimum | M33: 16.08 | N33: (8EA) | O33: REQUIRES 3 AA BATTERIES | P33: 6 HOUR TIMER REPEATS EVERY 18 HOURS | Q33: CONTINUOUS SWIRLING GLITTER, GENTLY FLIP TO LOOSEN GLITTER, TO AVOID DAMAGE DO NOT SHAKE | R33: INCLUDES USB CORD | S33: DOES NOT INCLUDE USB POWER ADAPTER | T33: DO NOT USE WITH USB POWER ADAPTER EXCEEDING 1.5 AMPS | U33: Artist: © Alexandria Designs, LLC
A34: F4202324 | B34: 660 | C34: 12 | D34: 31" Red Ball Ornament Spray | E34: 048893118587 | F34: 107600 | G34: https://www.razimports.com/media/catalog_product/ImagesFiles2/F4202324.jpg?quality=100&bg-color=255,255,255&fit=bounds&height=1000&width=1000&canvas=1000:1000 | H34: Made of PLASTIC | I34: Measures: 31" L | J34: RED | K34: 7.25 | L34: (12EA) Min. | M34: 6.10 | N34: (36EA) Case
A35: 4159136 | B35: 640 | C35: 16 | D35: *SB* 15.75" Christmas Message Block | E35: 048893217778 | F35: 93260 | G35: https://www.razimports.com/media/catalog_product/ImagesFiles2/4159136.jpg?quality=100&bg-color=255,255,255&fit=bounds&height=1000&width=1000&canvas=1000:1000 | H35: Made of FIR | I35: Measures: 15.75"L x 1.5"W x 3.25"H | J35: 2 ASST BLACK | K35: 7.40 | L35: (8EA) Minimum | M35: 4.00 | N35: (16EA) | O35: HANGS OR SITS | P35: Artist: © SAPNA; Licensed by SAPNA
A36: 4540514 | B36: 636 | C36: 4 | D36: 8" Cardinal and Birdhouse Lighted Water Lantern | E36: 048893943936 | F36: 103067 | G36: https://www.razimports.com/media/catalog_product/ImagesFiles2/4540514.jpg?quality=100&bg-color=255,255,255&fit=bounds&height=1000&width=1000&canvas=1000:1000 | H36: Made of PLASTIC | I36: Measures: 4.75" L x 3" W x 8" H | J36: BLACK | K36: 21.30 | L36: (4EA) Min. | M36: 18.85 | N36: (8EA) Case | O36: REQUIRES 3 AAA BATTERIES | P36: 6 HOUR TIMER REPEATS EVERY 18 HOURS | Q36: CONTINUOUS SWIRLING GLITTER, GENTLY FLIP TO LOOSEN GLITTER, TO AVOID DAMAGE DO NOT SHAKE | R36: INCLUDES USB CORD | S36: DOES NOT INCLUDE USB POWER ADAPTER | T36: DO NOT USE WITH USB POWER ADAPTER EXCEEDING 1.5 AMPS
A37: G4160801 | B37: 636 | C37: 6 | D37: 6' Felt Ball Garland | E37: 048893251239 | F37: 109826 | G37: https://www.razimports.com/media/catalog_product/ImagesFiles2/G4160801.jpg?quality=100&bg-color=255,255,255&fit=bounds&height=1000&width=1000&canvas=1000:1000 | H37: Made of POLYESTER | I37: Measures: 6' L | J37: RED | K37: 14.80 | L37: (6EA) Min. | M37: 12.55 | N37: (12EA) Case
A38: 4103430 | B38: 627 | C38: 12 | D38: *SB* 14.75" Posable Red and White Gnome | E38: 048893201456 | F38: 92912 | G38: https://www.razimports.com/media/catalog_product/ImagesFiles2/4103430.jpg?quality=100&bg-color=255,255,255&fit=bounds&height=1000&width=1000&canvas=1000:1000 | H38: Made of POLYESTER | I38: Measures: 9.5"L x 5.75"W x 14.75"H; 8.5"L x 7.5"W x 14.5"H; 8.5"L x 5.75"W x 14"H | J38: 3 ASST MULTICOLOR | K38: 21.70 | L38: (3EA) Minimum | M38: 11.10 | N38: (12EA) | O38: NOT INTENDED FOR CHILDREN | P38: FOR DECORATIVE USE ONLY
A39: 4559421 | B39: 624 | C39: 6 | D39: *DC* 3" X 6" Red Stripe Candle | E39: 048893429423 | F39: 104792 | G39: https://www.razimports.com/media/catalog_product/ImagesFiles2/4559421.jpg?quality=100&bg-color=255,255,255&fit=bounds&height=1000&width=1000&canvas=1000:1000 | H39: Made of PLASTIC | I39: Measures: 3" D x 6" H | J39: RED | K39: 9.65 | L39: (6EA) Min. | M39: 8.40 | N39: (12EA) Case | O39: REQUIRES 3 AAA BATTERIES | P39: 6 HOUR TIMER REPEATS EVERY 18 HOURS | Q39: BATTERY LIFE APPROX 120 HOURS | R39: REMOTE READY | S39: CAN BE USED WITH REMOTE #X4532915 | T39: DISCOUNTS CAPPED AT 10%
A40: F4516201 | B40: 624 | C40: 12 | D40: 29" Multicolor Ball Spray | E40: 048893938451 | F40: 108560 | G40: https://www.razimports.com/media/catalog_product/ImagesFiles2/F4516201.jpg?quality=100&bg-color=255,255,255&fit=bounds&height=1000&width=1000&canvas=1000:1000 | H40: Made of PLASTIC | I40: Measures: 29" L | J40: MULTICOLOR | K40: 6.65 | L40: (12EA) Min. | M40: 5.85 | N40: (24EA) Case
...

Sheet Stats
A1: sku | B1: qty_available | C1: min_order_qty | D1: MinCase | E1: IsOnSale | F1: Cases Available | G1: IsGreaterThan10 | H1: MinCaseCost | I1: MaxCaseCost | J1: TrueCost | K1: Amazon Cost | L1: UPC | M1: BareUPC | N1: Tier1RawGTIN | O1: Tier2RawGTIN | P1: Tier1GTIN | Q1: Tier2GTIN
A2: G3216179 | B2: =VLOOKUP(A2, Sheet1!A:Z, 2, FALSE) -> 2232 | C2: =VALUE(VLOOKUP(A2, Sheet1!A:Z, 3, FALSE)) -> 6 | D2: {=--_xlfn.TEXTJOIN("",TRUE,IF(ISNUMBER(MID(LEFT(MID(VLOOKUP(A2,Sheet1!A:Z,12,FALSE),2,99),FIND(")",VLOOKUP(A2,Sheet1!A:Z,12,FALSE))-2),ROW($1:$20),1)+0),MID(LEFT(MID(VLOOKUP(A2,Sheet1!A:Z,12,FALSE),2,99),FIND(")",VLOOKUP(A2,Sheet1!A:Z,12,FALSE))-2),ROW($1:$20),1),""))} -> 6 | E2: =IF(ISNUMBER(SEARCH("Minimum", VLOOKUP(A2, Sheet1!A:Z, 12, FALSE))), TRUE, FALSE) -> FALSE | F2: =QUOTIENT(B2, C2) -> 372 | G2: =VALUE(VLOOKUP(A2, Sheet1!A:Z, 11, FALSE))>=10 -> TRUE | H2: =VLOOKUP(A2, Sheet1!A:Z, 11, FALSE) -> 14.25 | I2: =VLOOKUP(A2, Sheet1!A:Z, 13, FALSE) -> 12.60 | J2: =IF(E2, I2, IF(C2<>D2,I2,H2)) -> 14.25 | K2: =(J2+20%)*2.8 -> 40.46 | L2: =VLOOKUP(A2, Sheet1!A:Z, 5, FALSE) -> 048893851880 | M2: =LEFT(L2, LEN(L2)-1) -> 04889385188 | N2: =(3000000000000+M2) -> 3004889385188 | O2: =(5000000000000+M2) -> 5004889385188 | P2: {=N2 & MOD(10 - MOD(SUMPRODUCT(MID(N2, ROW(INDIRECT("1:" & LEN(N2))), 1) * IF(MOD(ROW(INDIRECT("1:" & LEN(N2))), 2) = 0, 1, 3)), 10), 10)} -> 30048893851881
A3: 3911406 | B3: =VLOOKUP(A3, Sheet1!A:Z, 2, FALSE) -> 2082 | C3: =VALUE(VLOOKUP(A3, Sheet1!A:Z, 3, FALSE)) -> 2 | D3: {=--_xlfn.TEXTJOIN("",TRUE,IF(ISNUMBER(MID(LEFT(MID(VLOOKUP(A3,Sheet1!A:Z,12,FALSE),2,99),FIND(")",VLOOKUP(A3,Sheet1!A:Z,12,FALSE))-2),ROW($1:$20),1)+0),MID(LEFT(MID(VLOOKUP(A3,Sheet1!A:Z,12,FALSE),2,99),FIND(")",VLOOKUP(A3,Sheet1!A:Z,12,FALSE))-2),ROW($1:$20),1),""))} -> 2 | E3: =IF(ISNUMBER(SEARCH("Minimum", VLOOKUP(A3, Sheet1!A:Z, 12, FALSE))), TRUE, FALSE) -> FALSE | F3: =QUOTIENT(B3, C3) -> 1041 | G3: =VALUE(VLOOKUP(A3, Sheet1!A:Z, 11, FALSE))>=10 -> TRUE | H3: =VLOOKUP(A3, Sheet1!A:Z, 11, FALSE) -> 31.40 | I3: =VLOOKUP(A3, Sheet1!A:Z, 13, FALSE) -> 27.70 | J3: =IF(E3, I3, IF(C3<>D3,I3,H3)) -> 31.40 | K3: =(J3+20%)*2.8 -> 88.48 | L3: =VLOOKUP(A3, Sheet1!A:Z, 5, FALSE) -> 048893073978 | M3: =LEFT(L3, LEN(L3)-1) -> 04889307397 | N3: =(3000000000000+M3) -> 3004889307397 | O3: =(5000000000000+M3) -> 5004889307397 | P3: {=N3 & MOD(10 - MOD(SUMPRODUCT(MID(N3, ROW(INDIRECT("1:" & LEN(N3))), 1) * IF(MOD(ROW(INDIRECT("1:" & LEN(N3))), 2) = 0, 1, 3)), 10), 10)} -> 30048893073979
A4: G3416336 | B4: =VLOOKUP(A4, Sheet1!A:Z, 2, FALSE) -> 1920 | C4: =VALUE(VLOOKUP(A4, Sheet1!A:Z, 3, FALSE)) -> 6 | D4: {=--_xlfn.TEXTJOIN("",TRUE,IF(ISNUMBER(MID(LEFT(MID(VLOOKUP(A4,Sheet1!A:Z,12,FALSE),2,99),FIND(")",VLOOKUP(A4,Sheet1!A:Z,12,FALSE))-2),ROW($1:$20),1)+0),MID(LEFT(MID(VLOOKUP(A4,Sheet1!A:Z,12,FALSE),2,99),FIND(")",VLOOKUP(A4,Sheet1!A:Z,12,FALSE))-2),ROW($1:$20),1),""))} -> 6 | E4: =IF(ISNUMBER(SEARCH("Minimum", VLOOKUP(A4, Sheet1!A:Z, 12, FALSE))), TRUE, FALSE) -> FALSE | F4: =QUOTIENT(B4, C4) -> 320 | G4: =VALUE(VLOOKUP(A4, Sheet1!A:Z, 11, FALSE))>=10 -> TRUE | H4: =VLOOKUP(A4, Sheet1!A:Z, 11, FALSE) -> 14.90 | I4: =VLOOKUP(A4, Sheet1!A:Z, 13, FALSE) -> 13.20 | J4: =IF(E4, I4, IF(C4<>D4,I4,H4)) -> 14.90 | K4: =(J4+20%)*2.8 -> 42.28 | L4: =VLOOKUP(A4, Sheet1!A:Z, 5, FALSE) -> 048893987831 | M4: =LEFT(L4, LEN(L4)-1) -> 04889398783 | N4: =(3000000000000+M4) -> 3004889398783 | O4: =(5000000000000+M4) -> 5004889398783 | P4: {=N4 & MOD(10 - MOD(SUMPRODUCT(MID(N4, ROW(INDIRECT("1:" & LEN(N4))), 1) * IF(MOD(ROW(INDIRECT("1:" & LEN(N4))), 2) = 0, 1, 3)), 10), 10)} -> 30048893987832
A5: 4559488 | B5: =VLOOKUP(A5, Sheet1!A:Z, 2, FALSE) -> 1592 | C5: =VALUE(VLOOKUP(A5, Sheet1!A:Z, 3, FALSE)) -> 8 | D5: {=--_xlfn.TEXTJOIN("",TRUE,IF(ISNUMBER(MID(LEFT(MID(VLOOKUP(A5,Sheet1!A:Z,12,FALSE),2,99),FIND(")",VLOOKUP(A5,Sheet1!A:Z,12,FALSE))-2),ROW($1:$20),1)+0),MID(LEFT(MID(VLOOKUP(A5,Sheet1!A:Z,12,FALSE),2,99),FIND(")",VLOOKUP(A5,Sheet1!A:Z,12,FALSE))-2),ROW($1:$20),1),""))} -> 8 | E5: =IF(ISNUMBER(SEARCH("Minimum", VLOOKUP(A5, Sheet1!A:Z, 12, FALSE))), TRUE, FALSE) -> FALSE | F5: =QUOTIENT(B5, C5) -> 199 | G5: =VALUE(VLOOKUP(A5, Sheet1!A:Z, 11, FALSE))>=10 -> TRUE | H5: =VLOOKUP(A5, Sheet1!A:Z, 11, FALSE) -> 16.00 | I5: =VLOOKUP(A5, Sheet1!A:Z, 13, FALSE) -> 14.40 | J5: =IF(E5, I5, IF(C5<>D5,I5,H5)) -> 16.00 | K5: =(J5+20%)*2.8 -> 45.36 | L5: =VLOOKUP(A5, Sheet1!A:Z, 5, FALSE) -> 048893931223 | M5: =LEFT(L5, LEN(L5)-1) -> 04889393122 | N5: =(3000000000000+M5) -> 3004889393122 | O5: =(5000000000000+M5) -> 5004889393122 | P5: {=N5 & MOD(10 - MOD(SUMPRODUCT(MID(N5, ROW(INDIRECT("1:" & LEN(N5))), 1) * IF(MOD(ROW(INDIRECT("1:" & LEN(N5))), 2) = 0, 1, 3)), 10), 10)} -> 30048893931224
A6: 4533532 | B6: =VLOOKUP(A6, Sheet1!A:Z, 2, FALSE) -> 1536 | C6: =VALUE(VLOOKUP(A6, Sheet1!A:Z, 3, FALSE)) -> 24 | D6: {=--_xlfn.TEXTJOIN("",TRUE,IF(ISNUMBER(MID(LEFT(MID(VLOOKUP(A6,Sheet1!A:Z,12,FALSE),2,99),FIND(")",VLOOKUP(A6,Sheet1!A:Z,12,FALSE))-2),ROW($1:$20),1)+0),MID(LEFT(MID(VLOOKUP(A6,Sheet1!A:Z,12,FALSE),2,99),FIND(")",VLOOKUP(A6,Sheet1!A:Z,12,FALSE))-2),ROW($1:$20),1),""))} -> 24 | E6: =IF(ISNUMBER(SEARCH("Minimum", VLOOKUP(A6, Sheet1!A:Z, 12, FALSE))), TRUE, FALSE) -> FALSE | F6: =QUOTIENT(B6, C6) -> 64 | G6: =VALUE(VLOOKUP(A6, Sheet1!A:Z, 11, FALSE))>=10 -> FALSE | H6: =VLOOKUP(A6, Sheet1!A:Z, 11, FALSE) -> 2.75 | I6: =VLOOKUP(A6, Sheet1!A:Z, 13, FALSE) -> 2.45 | J6: =IF(E6, I6, IF(C6<>D6,I6,H6)) -> 2.75 | K6: =(J6+20%)*2.8 -> 8.26 | L6: =VLOOKUP(A6, Sheet1!A:Z, 5, FALSE) -> 048893931292 | M6: =LEFT(L6, LEN(L6)-1) -> 04889393129 | N6: =(3000000000000+M6) -> 3004889393129 | O6: =(5000000000000+M6) -> 5004889393129 | P6: {=N6 & MOD(10 - MOD(SUMPRODUCT(MID(N6, ROW(INDIRECT("1:" & LEN(N6))), 1) * IF(MOD(ROW(INDIRECT("1:" & LEN(N6))), 2) = 0, 1, 3)), 10), 10)} -> 30048893931293
A7: 4124532 | B7: =VLOOKUP(A7, Sheet1!A:Z, 2, FALSE) -> 1212 | C7: =VALUE(VLOOKUP(A7, Sheet1!A:Z, 3, FALSE)) -> 24 | D7: {=--_xlfn.TEXTJOIN("",TRUE,IF(ISNUMBER(MID(LEFT(MID(VLOOKUP(A7,Sheet1!A:Z,12,FALSE),2,99),FIND(")",VLOOKUP(A7,Sheet1!A:Z,12,FALSE))-2),ROW($1:$20),1)+0),MID(LEFT(MID(VLOOKUP(A7,Sheet1!A:Z,12,FALSE),2,99),FIND(")",VLOOKUP(A7,Sheet1!A:Z,12,FALSE))-2),ROW($1:$20),1),""))} -> 6 | E7: =IF(ISNUMBER(SEARCH("Minimum", VLOOKUP(A7, Sheet1!A:Z, 12, FALSE))), TRUE, FALSE) -> TRUE | F7: =QUOTIENT(B7, C7) -> 50 | G7: =VALUE(VLOOKUP(A7, Sheet1!A:Z, 11, FALSE))>=10 -> FALSE | H7: =VLOOKUP(A7, Sheet1!A:Z, 11, FALSE) -> 7.00 | I7: =VLOOKUP(A7, Sheet1!A:Z, 13, FALSE) -> 3.60 | J7: =IF(E7, I7, IF(C7<>D7,I7,H7)) -> 3.60 | K7: =(J7+20%)*2.8 -> 10.64 | L7: =VLOOKUP(A7, Sheet1!A:Z, 5, FALSE) -> 048893212469 | M7: =LEFT(L7, LEN(L7)-1) -> 04889321246 | N7: =(3000000000000+M7) -> 3004889321246 | O7: =(5000000000000+M7) -> 5004889321246 | P7: {=N7 & MOD(10 - MOD(SUMPRODUCT(MID(N7, ROW(INDIRECT("1:" & LEN(N7))), 1) * IF(MOD(ROW(INDIRECT("1:" & LEN(N7))), 2) = 0, 1, 3)), 10), 10)} -> 30048893212460
A8: 4432922 | B8: =VLOOKUP(A8, Sheet1!A:Z, 2, FALSE) -> 1200 | C8: =VALUE(VLOOKUP(A8, Sheet1!A:Z, 3, FALSE)) -> 8 | D8: {=--_xlfn.TEXTJOIN("",TRUE,IF(ISNUMBER(MID(LEFT(MID(VLOOKUP(A8,Sheet1!A:Z,12,FALSE),2,99),FIND(")",VLOOKUP(A8,Sheet1!A:Z,12,FALSE))-2),ROW($1:$20),1)+0),MID(LEFT(MID(VLOOKUP(A8,Sheet1!A:Z,12,FALSE),2,99),FIND(")",VLOOKUP(A8,Sheet1!A:Z,12,FALSE))-2),ROW($1:$20),1),""))} -> 8 | E8: =IF(ISNUMBER(SEARCH("Minimum", VLOOKUP(A8, Sheet1!A:Z, 12, FALSE))), TRUE, FALSE) -> FALSE | F8: =QUOTIENT(B8, C8) -> 150 | G8: =VALUE(VLOOKUP(A8, Sheet1!A:Z, 11, FALSE))>=10 -> TRUE | H8: =VLOOKUP(A8, Sheet1!A:Z, 11, FALSE) -> 15.45 | I8: =VLOOKUP(A8, Sheet1!A:Z, 13, FALSE) -> 13.85 | J8: =IF(E8, I8, IF(C8<>D8,I8,H8)) -> 15.45 | K8: =(J8+20%)*2.8 -> 43.82 | L8: =VLOOKUP(A8, Sheet1!A:Z, 5, FALSE) -> 048893490805 | M8: =LEFT(L8, LEN(L8)-1) -> 04889349080 | N8: =(3000000000000+M8) -> 3004889349080 | O8: =(5000000000000+M8) -> 5004889349080 | P8: {=N8 & MOD(10 - MOD(SUMPRODUCT(MID(N8, ROW(INDIRECT("1:" & LEN(N8))), 1) * IF(MOD(ROW(INDIRECT("1:" & LEN(N8))), 2) = 0, 1, 3)), 10), 10)} -> 30048893490806
A9: 4324035 | B9: =VLOOKUP(A9, Sheet1!A:Z, 2, FALSE) -> 1180 | C9: =VALUE(VLOOKUP(A9, Sheet1!A:Z, 3, FALSE)) -> 10 | D9: {=--_xlfn.TEXTJOIN("",TRUE,IF(ISNUMBER(MID(LEFT(MID(VLOOKUP(A9,Sheet1!A:Z,12,FALSE),2,99),FIND(")",VLOOKUP(A9,Sheet1!A:Z,12,FALSE))-2),ROW($1:$20),1)+0),MID(LEFT(MID(VLOOKUP(A9,Sheet1!A:Z,12,FALSE),2,99),FIND(")",VLOOKUP(A9,Sheet1!A:Z,12,FALSE))-2),ROW($1:$20),1),""))} -> 10 | E9: =IF(ISNUMBER(SEARCH("Minimum", VLOOKUP(A9, Sheet1!A:Z, 12, FALSE))), TRUE, FALSE) -> FALSE | F9: =QUOTIENT(B9, C9) -> 118 | G9: =VALUE(VLOOKUP(A9, Sheet1!A:Z, 11, FALSE))>=10 -> TRUE | H9: =VLOOKUP(A9, Sheet1!A:Z, 11, FALSE) -> 20.75 | I9: =VLOOKUP(A9, Sheet1!A:Z, 13, FALSE) -> 18.55 | J9: =IF(E9, I9, IF(C9<>D9,I9,H9)) -> 20.75 | K9: =(J9+20%)*2.8 -> 58.66 | L9: =VLOOKUP(A9, Sheet1!A:Z, 5, FALSE) -> 048893546533 | M9: =LEFT(L9, LEN(L9)-1) -> 04889354653 | N9: =(3000000000000+M9) -> 3004889354653 | O9: =(5000000000000+M9) -> 5004889354653 | P9: {=N9 & MOD(10 - MOD(SUMPRODUCT(MID(N9, ROW(INDIRECT("1:" & LEN(N9))), 1) * IF(MOD(ROW(INDIRECT("1:" & LEN(N9))), 2) = 0, 1, 3)), 10), 10)} -> 30048893546534
A10: F4517615 | B10: =VLOOKUP(A10, Sheet1!A:Z, 2, FALSE) -> 1140 | C10: =VALUE(VLOOKUP(A10, Sheet1!A:Z, 3, FALSE)) -> 12 | D10: {=--_xlfn.TEXTJOIN("",TRUE,IF(ISNUMBER(MID(LEFT(MID(VLOOKUP(A10,Sheet1!A:Z,12,FALSE),2,99),FIND(")",VLOOKUP(A10,Sheet1!A:Z,12,FALSE))-2),ROW($1:$20),1)+0),MID(LEFT(MID(VLOOKUP(A10,Sheet1!A:Z,12,FALSE),2,99),FIND(")",VLOOKUP(A10,Sheet1!A:Z,12,FALSE))-2),ROW($1:$20),1),""))} -> 12 | E10: =IF(ISNUMBER(SEARCH("Minimum", VLOOKUP(A10, Sheet1!A:Z, 12, FALSE))), TRUE, FALSE) -> FALSE | F10: =QUOTIENT(B10, C10) -> 95 | G10: =VALUE(VLOOKUP(A10, Sheet1!A:Z, 11, FALSE))>=10 -> FALSE | H10: =VLOOKUP(A10, Sheet1!A:Z, 11, FALSE) -> 8.70 | I10: =VLOOKUP(A10, Sheet1!A:Z, 13, FALSE) -> 7.25 | J10: =IF(E10, I10, IF(C10<>D10,I10,H10)) -> 8.70 | K10: =(J10+20%)*2.8 -> 24.92 | L10: =VLOOKUP(A10, Sheet1!A:Z, 5, FALSE) -> 048893937966 | M10: =LEFT(L10, LEN(L10)-1) -> 04889393796 | N10: =(3000000000000+M10) -> 3004889393796 | O10: =(5000000000000+M10) -> 5004889393796 | P10: {=N10 & MOD(10 - MOD(SUMPRODUCT(MID(N10, ROW(INDIRECT("1:" & LEN(N10))), 1) * IF(MOD(ROW(INDIRECT("1:" & LEN(N10))), 2) = 0, 1, 3)), 10), 10)} -> 30048893937967
A11: G4516359 | B11: =VLOOKUP(A11, Sheet1!A:Z, 2, FALSE) -> 1104 | C11: =VALUE(VLOOKUP(A11, Sheet1!A:Z, 3, FALSE)) -> 12 | D11: {=--_xlfn.TEXTJOIN("",TRUE,IF(ISNUMBER(MID(LEFT(MID(VLOOKUP(A11,Sheet1!A:Z,12,FALSE),2,99),FIND(")",VLOOKUP(A11,Sheet1!A:Z,12,FALSE))-2),ROW($1:$20),1)+0),MID(LEFT(MID(VLOOKUP(A11,Sheet1!A:Z,12,FALSE),2,99),FIND(")",VLOOKUP(A11,Sheet1!A:Z,12,FALSE))-2),ROW($1:$20),1),""))} -> 12 | E11: =IF(ISNUMBER(SEARCH("Minimum", VLOOKUP(A11, Sheet1!A:Z, 12, FALSE))), TRUE, FALSE) -> FALSE | F11: =QUOTIENT(B11, C11) -> 92 | G11: =VALUE(VLOOKUP(A11, Sheet1!A:Z, 11, FALSE))>=10 -> TRUE | H11: =VLOOKUP(A11, Sheet1!A:Z, 11, FALSE) -> 10.35 | I11: =VLOOKUP(A11, Sheet1!A:Z, 13, FALSE) -> 8.95 | J11: =IF(E11, I11, IF(C11<>D11,I11,H11)) -> 10.35 | K11: =(J11+20%)*2.8 -> 29.54 | L11: =VLOOKUP(A11, Sheet1!A:Z, 5, FALSE) -> 048893425883 | M11: =LEFT(L11, LEN(L11)-1) -> 04889342588 | N11: =(3000000000000+M11) -> 3004889342588 | O11: =(5000000000000+M11) -> 5004889342588 | P11: {=N11 & MOD(10 - MOD(SUMPRODUCT(MID(N11, ROW(INDIRECT("1:" & LEN(N11))), 1) * IF(MOD(ROW(INDIRECT("1:" & LEN(N11))), 2) = 0, 1, 3)), 10), 10)} -> 30048893425884
A12: G4416416 | B12: =VLOOKUP(A12, Sheet1!A:Z, 2, FALSE) -> 1080 | C12: =VALUE(VLOOKUP(A12, Sheet1!A:Z, 3, FALSE)) -> 12 | D12: {=--_xlfn.TEXTJOIN("",TRUE,IF(ISNUMBER(MID(LEFT(MID(VLOOKUP(A12,Sheet1!A:Z,12,FALSE),2,99),FIND(")",VLOOKUP(A12,Sheet1!A:Z,12,FALSE))-2),ROW($1:$20),1)+0),MID(LEFT(MID(VLOOKUP(A12,Sheet1!A:Z,12,FALSE),2,99),FIND(")",VLOOKUP(A12,Sheet1!A:Z,12,FALSE))-2),ROW($1:$20),1),""))} -> 12 | E12: =IF(ISNUMBER(SEARCH("Minimum", VLOOKUP(A12, Sheet1!A:Z, 12, FALSE))), TRUE, FALSE) -> FALSE | F12: =QUOTIENT(B12, C12) -> 90 | G12: =VALUE(VLOOKUP(A12, Sheet1!A:Z, 11, FALSE))>=10 -> FALSE | H12: =VLOOKUP(A12, Sheet1!A:Z, 11, FALSE) -> 6.30 | I12: =VLOOKUP(A12, Sheet1!A:Z, 13, FALSE) -> 5.30 | J12: =IF(E12, I12, IF(C12<>D12,I12,H12)) -> 6.30 | K12: =(J12+20%)*2.8 -> 18.2 | L12: =VLOOKUP(A12, Sheet1!A:Z, 5, FALSE) -> 048893986865 | M12: =LEFT(L12, LEN(L12)-1) -> 04889398686 | N12: =(3000000000000+M12) -> 3004889398686 | O12: =(5000000000000+M12) -> 5004889398686 | P12: {=N12 & MOD(10 - MOD(SUMPRODUCT(MID(N12, ROW(INDIRECT("1:" & LEN(N12))), 1) * IF(MOD(ROW(INDIRECT("1:" & LEN(N12))), 2) = 0, 1, 3)), 10), 10)} -> 30048893986866
A13: G4516540 | B13: =VLOOKUP(A13, Sheet1!A:Z, 2, FALSE) -> 1056 | C13: =VALUE(VLOOKUP(A13, Sheet1!A:Z, 3, FALSE)) -> 12 | D13: {=--_xlfn.TEXTJOIN("",TRUE,IF(ISNUMBER(MID(LEFT(MID(VLOOKUP(A13,Sheet1!A:Z,12,FALSE),2,99),FIND(")",VLOOKUP(A13,Sheet1!A:Z,12,FALSE))-2),ROW($1:$20),1)+0),MID(LEFT(MID(VLOOKUP(A13,Sheet1!A:Z,12,FALSE),2,99),FIND(")",VLOOKUP(A13,Sheet1!A:Z,12,FALSE))-2),ROW($1:$20),1),""))} -> 12 | E13: =IF(ISNUMBER(SEARCH("Minimum", VLOOKUP(A13, Sheet1!A:Z, 12, FALSE))), TRUE, FALSE) -> FALSE | F13: =QUOTIENT(B13, C13) -> 88 | G13: =VALUE(VLOOKUP(A13, Sheet1!A:Z, 11, FALSE))>=10 -> FALSE | H13: =VLOOKUP(A13, Sheet1!A:Z, 11, FALSE) -> 6.30 | I13: =VLOOKUP(A13, Sheet1!A:Z, 13, FALSE) -> 5.30 | J13: =IF(E13, I13, IF(C13<>D13,I13,H13)) -> 6.30 | K13: =(J13+20%)*2.8 -> 18.2 | L13: =VLOOKUP(A13, Sheet1!A:Z, 5, FALSE) -> 048893425814 | M13: =LEFT(L13, LEN(L13)-1) -> 04889342581 | N13: =(3000000000000+M13) -> 3004889342581 | O13: =(5000000000000+M13) -> 5004889342581 | P13: {=N13 & MOD(10 - MOD(SUMPRODUCT(MID(N13, ROW(INDIRECT("1:" & LEN(N13))), 1) * IF(MOD(ROW(INDIRECT("1:" & LEN(N13))), 2) = 0, 1, 3)), 10), 10)} -> 30048893425815
... A1096: 4159123 | B1096: =VLOOKUP(A1096, Sheet1!A:Z, 2, FALSE) -> 3 | C1096: =VALUE(VLOOKUP(A1096, Sheet1!A:Z, 3, FALSE)) -> 6 | D1096: {=--_xlfn.TEXTJOIN("",TRUE,IF(ISNUMBER(MID(LEFT(MID(VLOOKUP(A1096,Sheet1!A:Z,12,FALSE),2,99),FIND(")",VLOOKUP(A1096,Sheet1!A:Z,12,FALSE))-2),ROW($1:$20),1)+0),MID(LEFT(MID(VLOOKUP(A1096,Sheet1!A:Z,12,FALSE),2,99),FIND(")",VLOOKUP(A1096,Sheet1!A:Z,12,FALSE))-2),ROW($1:$20),1),""))} -> 3 | E1096: =IF(ISNUMBER(SEARCH("Minimum", VLOOKUP(A1096, Sheet1!A:Z, 12, FALSE))), TRUE, FALSE) -> TRUE | F1096: =QUOTIENT(B1096, C1096) -> 0 | G1096: =VALUE(VLOOKUP(A1096, Sheet1!A:Z, 11, FALSE))>=10 -> TRUE | H1096: =VLOOKUP(A1096, Sheet1!A:Z, 11, FALSE) -> 25.80 | I1096: =VLOOKUP(A1096, Sheet1!A:Z, 13, FALSE) -> 13.30 | J1096: =IF(E1096, I1096, IF(C1096<>D1096,I1096,H1096)) -> 13.30 | K1096: =(J1096+20%)*2.8 -> 37.8 | L1096: =VLOOKUP(A1096, Sheet1!A:Z, 5, FALSE) -> 048893217709 | M1096: =LEFT(L1096, LEN(L1096)-1) -> 04889321770 | N1096: =(3000000000000+M1096) -> 3004889321770 | O1096: =(5000000000000+M1096) -> 5004889321770 | P1096: {=N1096 & MOD(10 - MOD(SUMPRODUCT(MID(N1096, ROW(INDIRECT("1:" & LEN(N1096))), 1) * IF(MOD(ROW(INDIRECT("1:" & LEN(N1096))), 2) = 0, 1, 3)), 10), 10)} -> 30048893217700
A1097: 4319251 | B1097: =VLOOKUP(A1097, Sheet1!A:Z, 2, FALSE) -> 3 | D1097: {=--_xlfn.TEXTJOIN("",TRUE,IF(ISNUMBER(MID(LEFT(MID(VLOOKUP(A1097,Sheet1!A:Z,12,FALSE),2,99),FIND(")",VLOOKUP(A1097,Sheet1!A:Z,12,FALSE))-2),ROW($1:$20),1)+0),MID(LEFT(MID(VLOOKUP(A1097,Sheet1!A:Z,12,FALSE),2,99),FIND(")",VLOOKUP(A1097,Sheet1!A:Z,12,FALSE))-2),ROW($1:$20),1),""))} -> 4 | E1097: =IF(ISNUMBER(SEARCH("Minimum", VLOOKUP(A1097, Sheet1!A:Z, 12, FALSE))), TRUE, FALSE) -> FALSE | F1097: =QUOTIENT(B1097, C1097) -> #DIV/0! | G1097: =VALUE(VLOOKUP(A1097, Sheet1!A:Z, 11, FALSE))>=10 -> TRUE | H1097: =VLOOKUP(A1097, Sheet1!A:Z, 11, FALSE) -> 28.20 | I1097: =VLOOKUP(A1097, Sheet1!A:Z, 13, FALSE) -> 25.05 | J1097: =IF(E1097, I1097, IF(C1097<>D1097,I1097,H1097)) -> 25.05 | K1097: =(J1097+20%)*2.8 -> 70.7 | L1097: =VLOOKUP(A1097, Sheet1!A:Z, 5, FALSE) -> 048893550554 | M1097: =LEFT(L1097, LEN(L1097)-1) -> 04889355055 | N1097: =(3000000000000+M1097) -> 3004889355055 | O1097: =(5000000000000+M1097) -> 5004889355055 | P1097: {=N1097 & MOD(10 - MOD(SUMPRODUCT(MID(N1097, ROW(INDIRECT("1:" & LEN(N1097))), 1) * IF(MOD(ROW(INDIRECT("1:" & LEN(N1097))), 2) = 0, 1, 3)), 10), 10)} -> 30048893550555
A1098: 4401613 | B1098: =VLOOKUP(A1098, Sheet1!A:Z, 2, FALSE) -> 3 | C1098: 6 | D1098: {=--_xlfn.TEXTJOIN("",TRUE,IF(ISNUMBER(MID(LEFT(MID(VLOOKUP(A1098,Sheet1!A:Z,12,FALSE),2,99),FIND(")",VLOOKUP(A1098,Sheet1!A:Z,12,FALSE))-2),ROW($1:$20),1)+0),MID(LEFT(MID(VLOOKUP(A1098,Sheet1!A:Z,12,FALSE),2,99),FIND(")",VLOOKUP(A1098,Sheet1!A:Z,12,FALSE))-2),ROW($1:$20),1),""))} -> 3 | E1098: =IF(ISNUMBER(SEARCH("Minimum", VLOOKUP(A1098, Sheet1!A:Z, 12, FALSE))), TRUE, FALSE) -> TRUE | F1098: =QUOTIENT(B1098, C1098) -> 0 | G1098: =VALUE(VLOOKUP(A1098, Sheet1!A:Z, 11, FALSE))>=10 -> TRUE | H1098: =VLOOKUP(A1098, Sheet1!A:Z, 11, FALSE) -> 22.00 | I1098: =VLOOKUP(A1098, Sheet1!A:Z, 13, FALSE) -> 11.85 | J1098: =IF(E1098, I1098, IF(C1098<>D1098,I1098,H1098)) -> 11.85 | K1098: =(J1098+20%)*2.8 -> 33.74 | L1098: =VLOOKUP(A1098, Sheet1!A:Z, 5, FALSE) -> 048893996239 | M1098: =LEFT(L1098, LEN(L1098)-1) -> 04889399623 | N1098: =(3000000000000+M1098) -> 3004889399623 | O1098: =(5000000000000+M1098) -> 5004889399623 | P1098: {=N1098 & MOD(10 - MOD(SUMPRODUCT(MID(N1098, ROW(INDIRECT("1:" & LEN(N1098))), 1) * IF(MOD(ROW(INDIRECT("1:" & LEN(N1098))), 2) = 0, 1, 3)), 10), 10)} -> 30048893996230
A1099: 4401637 | B1099: =VLOOKUP(A1099, Sheet1!A:Z, 2, FALSE) -> 3 | C1099: 4 | D1099: {=--_xlfn.TEXTJOIN("",TRUE,IF(ISNUMBER(MID(LEFT(MID(VLOOKUP(A1099,Sheet1!A:Z,12,FALSE),2,99),FIND(")",VLOOKUP(A1099,Sheet1!A:Z,12,FALSE))-2),ROW($1:$20),1)+0),MID(LEFT(MID(VLOOKUP(A1099,Sheet1!A:Z,12,FALSE),2,99),FIND(")",VLOOKUP(A1099,Sheet1!A:Z,12,FALSE))-2),ROW($1:$20),1),""))} -> 2 | E1099: =IF(ISNUMBER(SEARCH("Minimum", VLOOKUP(A1099, Sheet1!A:Z, 12, FALSE))), TRUE, FALSE) -> TRUE | F1099: =QUOTIENT(B1099, C1099) -> 0 | G1099: =VALUE(VLOOKUP(A1099, Sheet1!A:Z, 11, FALSE))>=10 -> TRUE | H1099: =VLOOKUP(A1099, Sheet1!A:Z, 11, FALSE) -> 77.00 | I1099: =VLOOKUP(A1099, Sheet1!A:Z, 13, FALSE) -> 41.40 | J1099: =IF(E1099, I1099, IF(C1099<>D1099,I1099,H1099)) -> 41.40 | K1099: =(J1099+20%)*2.8 -> 116.48 | L1099: =VLOOKUP(A1099, Sheet1!A:Z, 5, FALSE) -> 048893996123 | M1099: =LEFT(L1099, LEN(L1099)-1) -> 04889399612 | N1099: =(3000000000000+M1099) -> 3004889399612 | O1099: =(5000000000000+M1099) -> 5004889399612 | P1099: {=N1099 & MOD(10 - MOD(SUMPRODUCT(MID(N1099, ROW(INDIRECT("1:" & LEN(N1099))), 1) * IF(MOD(ROW(INDIRECT("1:" & LEN(N1099))), 2) = 0, 1, 3)), 10), 10)} -> 30048893996124
A1100: 4415583 | B1100: =VLOOKUP(A1100, Sheet1!A:Z, 2, FALSE) -> 3 | C1100: 3 | D1100: {=--_xlfn.TEXTJOIN("",TRUE,IF(ISNUMBER(MID(LEFT(MID(VLOOKUP(A1100,Sheet1!A:Z,12,FALSE),2,99),FIND(")",VLOOKUP(A1100,Sheet1!A:Z,12,FALSE))-2),ROW($1:$20),1)+0),MID(LEFT(MID(VLOOKUP(A1100,Sheet1!A:Z,12,FALSE),2,99),FIND(")",VLOOKUP(A1100,Sheet1!A:Z,12,FALSE))-2),ROW($1:$20),1),""))} -> 3 | E1100: =IF(ISNUMBER(SEARCH("Minimum", VLOOKUP(A1100, Sheet1!A:Z, 12, FALSE))), TRUE, FALSE) -> FALSE | F1100: =QUOTIENT(B1100, C1100) -> 1 | G1100: =VALUE(VLOOKUP(A1100, Sheet1!A:Z, 11, FALSE))>=10 -> TRUE | H1100: =VLOOKUP(A1100, Sheet1!A:Z, 11, FALSE) -> 39.40 | I1100: =VLOOKUP(A1100, Sheet1!A:Z, 13, FALSE) -> 34.95 | J1100: =IF(E1100, I1100, IF(C1100<>D1100,I1100,H1100)) -> 34.95 | K1100: =(J1100+20%)*2.8 -> 98.42 | L1100: =VLOOKUP(A1100, Sheet1!A:Z, 5, FALSE) -> 048893499082 | M1100: =LEFT(L1100, LEN(L1100)-1) -> 04889349908 | N1100: =(3000000000000+M1100) -> 3004889349908 | O1100: =(5000000000000+M1100) -> 5004889349908 | P1100: {=N1100 & MOD(10 - MOD(SUMPRODUCT(MID(N1100, ROW(INDIRECT("1:" & LEN(N1100))), 1) * IF(MOD(ROW(INDIRECT("1:" & LEN(N1100))), 2) = 0, 1, 3)), 10), 10)} -> 30048893499083
A1101: 4419630 | B1101: =VLOOKUP(A1101, Sheet1!A:Z, 2, FALSE) -> 3 | C1101: 4 | D1101: {=--_xlfn.TEXTJOIN("",TRUE,IF(ISNUMBER(MID(LEFT(MID(VLOOKUP(A1101,Sheet1!A:Z,12,FALSE),2,99),FIND(")",VLOOKUP(A1101,Sheet1!A:Z,12,FALSE))-2),ROW($1:$20),1)+0),MID(LEFT(MID(VLOOKUP(A1101,Sheet1!A:Z,12,FALSE),2,99),FIND(")",VLOOKUP(A1101,Sheet1!A:Z,12,FALSE))-2),ROW($1:$20),1),""))} -> 2 | E1101: =IF(ISNUMBER(SEARCH("Minimum", VLOOKUP(A1101, Sheet1!A:Z, 12, FALSE))), TRUE, FALSE) -> TRUE | F1101: =QUOTIENT(B1101, C1101) -> 0 | G1101: =VALUE(VLOOKUP(A1101, Sheet1!A:Z, 11, FALSE))>=10 -> TRUE | H1101: =VLOOKUP(A1101, Sheet1!A:Z, 11, FALSE) -> 41.50 | I1101: =VLOOKUP(A1101, Sheet1!A:Z, 13, FALSE) -> 22.20 | J1101: =IF(E1101, I1101, IF(C1101<>D1101,I1101,H1101)) -> 22.20 | K1101: =(J1101+20%)*2.8 -> 62.72 | L1101: =VLOOKUP(A1101, Sheet1!A:Z, 5, FALSE) -> 048893495152 | M1101: =LEFT(L1101, LEN(L1101)-1) -> 04889349515 | N1101: =(3000000000000+M1101) -> 3004889349515 | O1101: =(5000000000000+M1101) -> 5004889349515 | P1101: {=N1101 & MOD(10 - MOD(SUMPRODUCT(MID(N1101, ROW(INDIRECT("1:" & LEN(N1101))), 1) * IF(MOD(ROW(INDIRECT("1:" & LEN(N1101))), 2) = 0, 1, 3)), 10), 10)} -> 30048893495153
A1102: 4510368 | B1102: =VLOOKUP(A1102, Sheet1!A:Z, 2, FALSE) -> 3 | C1102: 3 | D1102: {=--_xlfn.TEXTJOIN("",TRUE,IF(ISNUMBER(MID(LEFT(MID(VLOOKUP(A1102,Sheet1!A:Z,12,FALSE),2,99),FIND(")",VLOOKUP(A1102,Sheet1!A:Z,12,FALSE))-2),ROW($1:$20),1)+0),MID(LEFT(MID(VLOOKUP(A1102,Sheet1!A:Z,12,FALSE),2,99),FIND(")",VLOOKUP(A1102,Sheet1!A:Z,12,FALSE))-2),ROW($1:$20),1),""))} -> 3 | E1102: =IF(ISNUMBER(SEARCH("Minimum", VLOOKUP(A1102, Sheet1!A:Z, 12, FALSE))), TRUE, FALSE) -> FALSE | F1102: =QUOTIENT(B1102, C1102) -> 1 | G1102: =VALUE(VLOOKUP(A1102, Sheet1!A:Z, 11, FALSE))>=10 -> TRUE | H1102: =VLOOKUP(A1102, Sheet1!A:Z, 11, FALSE) -> 42.30 | I1102: =VLOOKUP(A1102, Sheet1!A:Z, 13, FALSE) -> 37.25 | J1102: =IF(E1102, I1102, IF(C1102<>D1102,I1102,H1102)) -> 37.25 | K1102: =(J1102+20%)*2.8 -> 104.86 | L1102: =VLOOKUP(A1102, Sheet1!A:Z, 5, FALSE) -> 048893959890 | M1102: =LEFT(L1102, LEN(L1102)-1) -> 04889395989 | N1102: =(3000000000000+M1102) -> 3004889395989 | O1102: =(5000000000000+M1102) -> 5004889395989 | P1102: {=N1102 & MOD(10 - MOD(SUMPRODUCT(MID(N1102, ROW(INDIRECT("1:" & LEN(N1102))), 1) * IF(MOD(ROW(INDIRECT("1:" & LEN(N1102))), 2) = 0, 1, 3)), 10), 10)} -> 30048893959891
A1103: 4511646 | B1103: =VLOOKUP(A1103, Sheet1!A:Z, 2, FALSE) -> 3 | C1103: 3 | D1103: {=--_xlfn.TEXTJOIN("",TRUE,IF(ISNUMBER(MID(LEFT(MID(VLOOKUP(A1103,Sheet1!A:Z,12,FALSE),2,99),FIND(")",VLOOKUP(A1103,Sheet1!A:Z,12,FALSE))-2),ROW($1:$20),1)+0),MID(LEFT(MID(VLOOKUP(A1103,Sheet1!A:Z,12,FALSE),2,99),FIND(")",VLOOKUP(A1103,Sheet1!A:Z,12,FALSE))-2),ROW($1:$20),1),""))} -> 3 | E1103: =IF(ISNUMBER(SEARCH("Minimum", VLOOKUP(A1103, Sheet1!A:Z, 12, FALSE))), TRUE, FALSE) -> FALSE | F1103: =QUOTIENT(B1103, C1103) -> 1 | G1103: =VALUE(VLOOKUP(A1103, Sheet1!A:Z, 11, FALSE))>=10 -> TRUE | H1103: =VLOOKUP(A1103, Sheet1!A:Z, 11, FALSE) -> 29.30 | I1103: =VLOOKUP(A1103, Sheet1!A:Z, 13, FALSE) -> 26.10 | J1103: =IF(E1103, I1103, IF(C1103<>D1103,I1103,H1103)) -> 26.10 | K1103: =(J1103+20%)*2.8 -> 73.64 | L1103: =VLOOKUP(A1103, Sheet1!A:Z, 5, FALSE) -> 048893958008 | M1103: =LEFT(L1103, LEN(L1103)-1) -> 04889395800 | N1103: =(3000000000000+M1103) -> 3004889395800 | O1103: =(5000000000000+M1103) -> 5004889395800 | P1103: {=N1103 & MOD(10 - MOD(SUMPRODUCT(MID(N1103, ROW(INDIRECT("1:" & LEN(N1103))), 1) * IF(MOD(ROW(INDIRECT("1:" & LEN(N1103))), 2) = 0, 1, 3)), 10), 10)} -> 30048893958009
A1104: 4519212 | B1104: =VLOOKUP(A1104, Sheet1!A:Z, 2, FALSE) -> 3 | C1104: 3 | D1104: {=--_xlfn.TEXTJOIN("",TRUE,IF(ISNUMBER(MID(LEFT(MID(VLOOKUP(A1104,Sheet1!A:Z,12,FALSE),2,99),FIND(")",VLOOKUP(A1104,Sheet1!A:Z,12,FALSE))-2),ROW($1:$20),1)+0),MID(LEFT(MID(VLOOKUP(A1104,Sheet1!A:Z,12,FALSE),2,99),FIND(")",VLOOKUP(A1104,Sheet1!A:Z,12,FALSE))-2),ROW($1:$20),1),""))} -> 3 | E1104: =IF(ISNUMBER(SEARCH("Minimum", VLOOKUP(A1104, Sheet1!A:Z, 12, FALSE))), TRUE, FALSE) -> FALSE | F1104: =QUOTIENT(B1104, C1104) -> 1 | G1104: =VALUE(VLOOKUP(A1104, Sheet1!A:Z, 11, FALSE))>=10 -> TRUE | H1104: =VLOOKUP(A1104, Sheet1!A:Z, 11, FALSE) -> 36.00 | I1104: =VLOOKUP(A1104, Sheet1!A:Z, 13, FALSE) -> 31.95 | J1104: =IF(E1104, I1104, IF(C1104<>D1104,I1104,H1104)) -> 31.95 | K1104: =(J1104+20%)*2.8 -> 90.02 | L1104: =VLOOKUP(A1104, Sheet1!A:Z, 5, FALSE) -> 048893952181 | M1104: =LEFT(L1104, LEN(L1104)-1) -> 04889395218 | N1104: =(3000000000000+M1104) -> 3004889395218 | O1104: =(5000000000000+M1104) -> 5004889395218 | P1104: {=N1104 & MOD(10 - MOD(SUMPRODUCT(MID(N1104, ROW(INDIRECT("1:" & LEN(N1104))), 1) * IF(MOD(ROW(INDIRECT("1:" & LEN(N1104))), 2) = 0, 1, 3)), 10), 10)} -> 30048893952182
A1105: 4524989 | B1105: =VLOOKUP(A1105, Sheet1!A:Z, 2, FALSE) -> 3 | C1105: 3 | D1105: {=--_xlfn.TEXTJOIN("",TRUE,IF(ISNUMBER(MID(LEFT(MID(VLOOKUP(A1105,Sheet1!A:Z,12,FALSE),2,99),FIND(")",VLOOKUP(A1105,Sheet1!A:Z,12,FALSE))-2),ROW($1:$20),1)+0),MID(LEFT(MID(VLOOKUP(A1105,Sheet1!A:Z,12,FALSE),2,99),FIND(")",VLOOKUP(A1105,Sheet1!A:Z,12,FALSE))-2),ROW($1:$20),1),""))} -> 3 | E1105: =IF(ISNUMBER(SEARCH("Minimum", VLOOKUP(A1105, Sheet1!A:Z, 12, FALSE))), TRUE, FALSE) -> FALSE | F1105: =QUOTIENT(B1105, C1105) -> 1 | G1105: =VALUE(VLOOKUP(A1105, Sheet1!A:Z, 11, FALSE))>=10 -> TRUE | H1105: =VLOOKUP(A1105, Sheet1!A:Z, 11, FALSE) -> 39.60 | I1105: =VLOOKUP(A1105, Sheet1!A:Z, 13, FALSE) -> 35.05 | J1105: =IF(E1105, I1105, IF(C1105<>D1105,I1105,H1105)) -> 35.05 | K1105: =(J1105+20%)*2.8 -> 98.7 | L1105: =VLOOKUP(A1105, Sheet1!A:Z, 5, FALSE) -> 048893435554 | M1105: =LEFT(L1105, LEN(L1105)-1) -> 04889343555 | N1105: =(3000000000000+M1105) -> 3004889343555 | O1105: =(5000000000000+M1105) -> 5004889343555 | P1105: {=N1105 & MOD(10 - MOD(SUMPRODUCT(MID(N1105, ROW(INDIRECT("1:" & LEN(N1105))), 1) * IF(MOD(ROW(INDIRECT("1:" & LEN(N1105))), 2) = 0, 1, 3)), 10), 10)} -> 30048893435555
A1106: 4557381 | B1106: =VLOOKUP(A1106, Sheet1!A:Z, 2, FALSE) -> 3 | C1106: 3 | D1106: {=--_xlfn.TEXTJOIN("",TRUE,IF(ISNUMBER(MID(LEFT(MID(VLOOKUP(A1106,Sheet1!A:Z,12,FALSE),2,99),FIND(")",VLOOKUP(A1106,Sheet1!A:Z,12,FALSE))-2),ROW($1:$20),1)+0),MID(LEFT(MID(VLOOKUP(A1106,Sheet1!A:Z,12,FALSE),2,99),FIND(")",VLOOKUP(A1106,Sheet1!A:Z,12,FALSE))-2),ROW($1:$20),1),""))} -> 3 | E1106: =IF(ISNUMBER(SEARCH("Minimum", VLOOKUP(A1106, Sheet1!A:Z, 12, FALSE))), TRUE, FALSE) -> FALSE | F1106: =QUOTIENT(B1106, C1106) -> 1 | G1106: =VALUE(VLOOKUP(A1106, Sheet1!A:Z, 11, FALSE))>=10 -> TRUE | H1106: =VLOOKUP(A1106, Sheet1!A:Z, 11, FALSE) -> 23.95 | I1106: =VLOOKUP(A1106, Sheet1!A:Z, 13, FALSE) -> 21.10 | J1106: =IF(E1106, I1106, IF(C1106<>D1106,I1106,H1106)) -> 21.10 | K1106: =(J1106+20%)*2.8 -> 59.64 | L1106: =VLOOKUP(A1106, Sheet1!A:Z, 5, FALSE) -> 048893430221 | M1106: =LEFT(L1106, LEN(L1106)-1) -> 04889343022 | N1106: =(3000000000000+M1106) -> 3004889343022 | O1106: =(5000000000000+M1106) -> 5004889343022 | P1106: {=N1106 & MOD(10 - MOD(SUMPRODUCT(MID(N1106, ROW(INDIRECT("1:" & LEN(N1106))), 1) * IF(MOD(ROW(INDIRECT("1:" & LEN(N1106))), 2) = 0, 1, 3)), 10), 10)} -> 30048893430222
A1107: 4559179 | B1107: =VLOOKUP(A1107, Sheet1!A:Z, 2, FALSE) -> 3 | C1107: 2 | D1107: {=--_xlfn.TEXTJOIN("",TRUE,IF(ISNUMBER(MID(LEFT(MID(VLOOKUP(A1107,Sheet1!A:Z,12,FALSE),2,99),FIND(")",VLOOKUP(A1107,Sheet1!A:Z,12,FALSE))-2),ROW($1:$20),1)+0),MID(LEFT(MID(VLOOKUP(A1107,Sheet1!A:Z,12,FALSE),2,99),FIND(")",VLOOKUP(A1107,Sheet1!A:Z,12,FALSE))-2),ROW($1:$20),1),""))} -> 2 | E1107: =IF(ISNUMBER(SEARCH("Minimum", VLOOKUP(A1107, Sheet1!A:Z, 12, FALSE))), TRUE, FALSE) -> FALSE | F1107: =QUOTIENT(B1107, C1107) -> 1 | G1107: =VALUE(VLOOKUP(A1107, Sheet1!A:Z, 11, FALSE))>=10 -> TRUE | H1107: =VLOOKUP(A1107, Sheet1!A:Z, 11, FALSE) -> 42.40 | I1107: =VLOOKUP(A1107, Sheet1!A:Z, 13, FALSE) -> 37.50 | J1107: =IF(E1107, I1107, IF(C1107<>D1107,I1107,H1107)) -> 37.50 | K1107: =(J1107+20%)*2.8 -> 105.56 | L1107: =VLOOKUP(A1107, Sheet1!A:Z, 5, FALSE) -> 048893940409 | M1107: =LEFT(L1107, LEN(L1107)-1) -> 04889394040 | N1107: =(3000000000000+M1107) -> 3004889394040 | O1107: =(5000000000000+M1107) -> 5004889394040 | P1107: {=N1107 & MOD(10 - MOD(SUMPRODUCT(MID(N1107, ROW(INDIRECT("1:" & LEN(N1107))), 1) * IF(MOD(ROW(INDIRECT("1:" & LEN(N1107))), 2) = 0, 1, 3)), 10), 10)} -> 30048893940400
A1108: T4252035 | B1108: =VLOOKUP(A1108, Sheet1!A:Z, 2, FALSE) -> 3 | C1108: 4 | D1108: {=--_xlfn.TEXTJOIN("",TRUE,IF(ISNUMBER(MID(LEFT(MID(VLOOKUP(A1108,Sheet1!A:Z,12,FALSE),2,99),FIND(")",VLOOKUP(A1108,Sheet1!A:Z,12,FALSE))-2),ROW($1:$20),1)+0),MID(LEFT(MID(VLOOKUP(A1108,Sheet1!A:Z,12,FALSE),2,99),FIND(")",VLOOKUP(A1108,Sheet1!A:Z,12,FALSE))-2),ROW($1:$20),1),""))} -> 1 | E1108: =IF(ISNUMBER(SEARCH("Minimum", VLOOKUP(A1108, Sheet1!A:Z, 12, FALSE))), TRUE, FALSE) -> TRUE | F1108: =QUOTIENT(B1108, C1108) -> 0 | G1108: =VALUE(VLOOKUP(A1108, Sheet1!A:Z, 11, FALSE))>=10 -> TRUE | H1108: =VLOOKUP(A1108, Sheet1!A:Z, 11, FALSE) -> 485.00 | I1108: =VLOOKUP(A1108, Sheet1!A:Z, 13, FALSE) -> 261.00 | J1108: =IF(E1108, I1108, IF(C1108<>D1108,I1108,H1108)) -> 261.00 | K1108: =(J1108+20%)*2.8 -> 731.36 | L1108: =VLOOKUP(A1108, Sheet1!A:Z, 5, FALSE) -> 048893753719 | M1108: =LEFT(L1108, LEN(L1108)-1) -> 04889375371 | N1108: =(3000000000000+M1108) -> 3004889375371 | O1108: =(5000000000000+M1108) -> 5004889375371 | P1108: {=N1108 & MOD(10 - MOD(SUMPRODUCT(MID(N1108, ROW(INDIRECT("1:" & LEN(N1108))), 1) * IF(MOD(ROW(INDIRECT("1:" & LEN(N1108))), 2) = 0, 1, 3)), 10), 10)} -> 30048893753710
A1109: 3817594 | B1109: =VLOOKUP(A1109, Sheet1!A:Z, 2, FALSE) -> 2 | C1109: 2 | D1109: {=--_xlfn.TEXTJOIN("",TRUE,IF(ISNUMBER(MID(LEFT(MID(VLOOKUP(A1109,Sheet1!A:Z,12,FALSE),2,99),FIND(")",VLOOKUP(A1109,Sheet1!A:Z,12,FALSE))-2),ROW($1:$20),1)+0),MID(LEFT(MID(VLOOKUP(A1109,Sheet1!A:Z,12,FALSE),2,99),FIND(")",VLOOKUP(A1109,Sheet1!A:Z,12,FALSE))-2),ROW($1:$20),1),""))} -> 2 | E1109: =IF(ISNUMBER(SEARCH("Minimum", VLOOKUP(A1109, Sheet1!A:Z, 12, FALSE))), TRUE, FALSE) -> FALSE | F1109: =QUOTIENT(B1109, C1109) -> 1 | G1109: =VALUE(VLOOKUP(A1109, Sheet1!A:Z, 11, FALSE))>=10 -> TRUE | H1109: =VLOOKUP(A1109, Sheet1!A:Z, 11, FALSE) -> 29.50 | I1109: =VLOOKUP(A1109, Sheet1!A:Z, 13, FALSE) -> 24.90 | J1109: =IF(E1109, I1109, IF(C1109<>D1109,I1109,H1109)) -> 24.90 | K1109: =(J1109+20%)*2.8 -> 70.28 | L1109: =VLOOKUP(A1109, Sheet1!A:Z, 5, FALSE) -> 048893222673 | M1109: =LEFT(L1109, LEN(L1109)-1) -> 04889322267 | N1109: =(3000000000000+M1109) -> 3004889322267 | O1109: =(5000000000000+M1109) -> 5004889322267 | P1109: {=N1109 & MOD(10 - MOD(SUMPRODUCT(MID(N1109, ROW(INDIRECT("1:" & LEN(N1109))), 1) * IF(MOD(ROW(INDIRECT("1:" & LEN(N1109))), 2) = 0, 1, 3)), 10), 10)} -> 30048893222674
A1110: 3919039 | B1110: =VLOOKUP(A1110, Sheet1!A:Z, 2, FALSE) -> 2 | D1110: {=--_xlfn.TEXTJOIN("",TRUE,IF(ISNUMBER(MID(LEFT(MID(VLOOKUP(A1110,Sheet1!A:Z,12,FALSE),2,99),FIND(")",VLOOKUP(A1110,Sheet1!A:Z,12,FALSE))-2),ROW($1:$20),1)+0),MID(LEFT(MID(VLOOKUP(A1110,Sheet1!A:Z,12,FALSE),2,99),FIND(")",VLOOKUP(A1110,Sheet1!A:Z,12,FALSE))-2),ROW($1:$20),1),""))} -> 4 | E1110: =IF(ISNUMBER(SEARCH("Minimum", VLOOKUP(A1110, Sheet1!A:Z, 12, FALSE))), TRUE, FALSE) -> FALSE | F1110: =QUOTIENT(B1110, C1110) -> #DIV/0! | G1110: =VALUE(VLOOKUP(A1110, Sheet1!A:Z, 11, FALSE))>=10 -> TRUE | H1110: =VLOOKUP(A1110, Sheet1!A:Z, 11, FALSE) -> 26.90 | I1110: =VLOOKUP(A1110, Sheet1!A:Z, 13, FALSE) -> 24.30 | J1110: =IF(E1110, I1110, IF(C1110<>D1110,I1110,H1110)) -> 24.30 | K1110: =(J1110+20%)*2.8 -> 68.6 | L1110: =VLOOKUP(A1110, Sheet1!A:Z, 5, FALSE) -> 048893079567 | M1110: =LEFT(L1110, LEN(L1110)-1) -> 04889307956 | N1110: =(3000000000000+M1110) -> 3004889307956 | O1110: =(5000000000000+M1110) -> 5004889307956 | P1110: {=N1110 & MOD(10 - MOD(SUMPRODUCT(MID(N1110, ROW(INDIRECT("1:" & LEN(N1110))), 1) * IF(MOD(ROW(INDIRECT("1:" & LEN(N1110))), 2) = 0, 1, 3)), 10), 10)} -> 30048893079568
A1111: 4228006 | B1111: =VLOOKUP(A1111, Sheet1!A:Z, 2, FALSE) -> 2 | C1111: 4 | D1111: {=--_xlfn.TEXTJOIN("",TRUE,IF(ISNUMBER(MID(LEFT(MID(VLOOKUP(A1111,Sheet1!A:Z,12,FALSE),2,99),FIND(")",VLOOKUP(A1111,Sheet1!A:Z,12,FALSE))-2),ROW($1:$20),1)+0),MID(LEFT(MID(VLOOKUP(A1111,Sheet1!A:Z,12,FALSE),2,99),FIND(")",VLOOKUP(A1111,Sheet1!A:Z,12,FALSE))-2),ROW($1:$20),1),""))} -> 2 | E1111: =IF(ISNUMBER(SEARCH("Minimum", VLOOKUP(A1111, Sheet1!A:Z, 12, FALSE))), TRUE, FALSE) -> TRUE | F1111: =QUOTIENT(B1111, C1111) -> 0 | G1111: =VALUE(VLOOKUP(A1111, Sheet1!A:Z, 11, FALSE))>=10 -> TRUE | H1111: =VLOOKUP(A1111, Sheet1!A:Z, 11, FALSE) -> 84.00 | I1111: =VLOOKUP(A1111, Sheet1!A:Z, 13, FALSE) -> 44.70 | J1111: =IF(E1111, I1111, IF(C1111<>D1111,I1111,H1111)) -> 44.70 | K1111: =(J1111+20%)*2.8 -> 125.72 | L1111: =VLOOKUP(A1111, Sheet1!A:Z, 5, FALSE) -> 048893147082 | M1111: =LEFT(L1111, LEN(L1111)-1) -> 04889314708 | N1111: =(3000000000000+M1111) -> 3004889314708 | O1111: =(5000000000000+M1111) -> 5004889314708 | P1111: {=N1111 & MOD(10 - MOD(SUMPRODUCT(MID(N1111, ROW(INDIRECT("1:" & LEN(N1111))), 1) * IF(MOD(ROW(INDIRECT("1:" & LEN(N1111))), 2) = 0, 1, 3)), 10), 10)} -> 30048893147083
A1112: 4300758 | B1112: =VLOOKUP(A1112, Sheet1!A:Z, 2, FALSE) -> 2 | D1112: {=--_xlfn.TEXTJOIN("",TRUE,IF(ISNUMBER(MID(LEFT(MID(VLOOKUP(A1112,Sheet1!A:Z,12,FALSE),2,99),FIND(")",VLOOKUP(A1112,Sheet1!A:Z,12,FALSE))-2),ROW($1:$20),1)+0),MID(LEFT(MID(VLOOKUP(A1112,Sheet1!A:Z,12,FALSE),2,99),FIND(")",VLOOKUP(A1112,Sheet1!A:Z,12,FALSE))-2),ROW($1:$20),1),""))} -> 4 | E1112: =IF(ISNUMBER(SEARCH("Minimum", VLOOKUP(A1112, Sheet1!A:Z, 12, FALSE))), TRUE, FALSE) -> FALSE | F1112: =QUOTIENT(B1112, C1112) -> #DIV/0! | G1112: =VALUE(VLOOKUP(A1112, Sheet1!A:Z, 11, FALSE))>=10 -> TRUE | H1112: =VLOOKUP(A1112, Sheet1!A:Z, 11, FALSE) -> 25.05 | I1112: =VLOOKUP(A1112, Sheet1!A:Z, 13, FALSE) -> 22.15 | J1112: =IF(E1112, I1112, IF(C1112<>D1112,I1112,H1112)) -> 22.15 | K1112: =(J1112+20%)*2.8 -> 62.58 | L1112: =VLOOKUP(A1112, Sheet1!A:Z, 5, FALSE) -> 048893083922 | M1112: =LEFT(L1112, LEN(L1112)-1) -> 04889308392 | N1112: =(3000000000000+M1112) -> 3004889308392 | O1112: =(5000000000000+M1112) -> 5004889308392 | P1112: {=N1112 & MOD(10 - MOD(SUMPRODUCT(MID(N1112, ROW(INDIRECT("1:" & LEN(N1112))), 1) * IF(MOD(ROW(INDIRECT("1:" & LEN(N1112))), 2) = 0, 1, 3)), 10), 10)} -> 30048893083923
A1113: 4411609 | B1113: =VLOOKUP(A1113, Sheet1!A:Z, 2, FALSE) -> 2 | C1113: 4 | D1113: {=--_xlfn.TEXTJOIN("",TRUE,IF(ISNUMBER(MID(LEFT(MID(VLOOKUP(A1113,Sheet1!A:Z,12,FALSE),2,99),FIND(")",VLOOKUP(A1113,Sheet1!A:Z,12,FALSE))-2),ROW($1:$20),1)+0),MID(LEFT(MID(VLOOKUP(A1113,Sheet1!A:Z,12,FALSE),2,99),FIND(")",VLOOKUP(A1113,Sheet1!A:Z,12,FALSE))-2),ROW($1:$20),1),""))} -> 2 | E1113: =IF(ISNUMBER(SEARCH("Minimum", VLOOKUP(A1113, Sheet1!A:Z, 12, FALSE))), TRUE, FALSE) -> TRUE | F1113: =QUOTIENT(B1113, C1113) -> 0 | G1113: =VALUE(VLOOKUP(A1113, Sheet1!A:Z, 11, FALSE))>=10 -> TRUE | H1113: =VLOOKUP(A1113, Sheet1!A:Z, 11, FALSE) -> 50.00 | I1113: =VLOOKUP(A1113, Sheet1!A:Z, 13, FALSE) -> 27.00 | J1113: =IF(E1113, I1113, IF(C1113<>D1113,I1113,H1113)) -> 27.00 | K1113: =(J1113+20%)*2.8 -> 76.16 | L1113: =VLOOKUP(A1113, Sheet1!A:Z, 5, FALSE) -> 048893995218 | M1113: =LEFT(L1113, LEN(L1113)-1) -> 04889399521 | N1113: =(3000000000000+M1113) -> 3004889399521 | O1113: =(5000000000000+M1113) -> 5004889399521 | P1113: {=N1113 & MOD(10 - MOD(SUMPRODUCT(MID(N1113, ROW(INDIRECT("1:" & LEN(N1113))), 1) * IF(MOD(ROW(INDIRECT("1:" & LEN(N1113))), 2) = 0, 1, 3)), 10), 10)} -> 30048893995219
A1114: 4416230 | B1114: =VLOOKUP(A1114, Sheet1!A:Z, 2, FALSE) -> 2 | C1114: 2 | D1114: {=--_xlfn.TEXTJOIN("",TRUE,IF(ISNUMBER(MID(LEFT(MID(VLOOKUP(A1114,Sheet1!A:Z,12,FALSE),2,99),FIND(")",VLOOKUP(A1114,Sheet1!A:Z,12,FALSE))-2),ROW($1:$20),1)+0),MID(LEFT(MID(VLOOKUP(A1114,Sheet1!A:Z,12,FALSE),2,99),FIND(")",VLOOKUP(A1114,Sheet1!A:Z,12,FALSE))-2),ROW($1:$20),1),""))} -> 2 | E1114: =IF(ISNUMBER(SEARCH("Minimum", VLOOKUP(A1114, Sheet1!A:Z, 12, FALSE))), TRUE, FALSE) -> FALSE | F1114: =QUOTIENT(B1114, C1114) -> 1 | G1114: =VALUE(VLOOKUP(A1114, Sheet1!A:Z, 11, FALSE))>=10 -> TRUE | H1114: =VLOOKUP(A1114, Sheet1!A:Z, 11, FALSE) -> 51.10 | I1114: =VLOOKUP(A1114, Sheet1!A:Z, 13, FALSE) -> 45.25 | J1114: =IF(E1114, I1114, IF(C1114<>D1114,I1114,H1114)) -> 45.25 | K1114: =(J1114+20%)*2.8 -> 127.26 | L1114: =VLOOKUP(A1114, Sheet1!A:Z, 5, FALSE) -> 048893994204 | M1114: =LEFT(L1114, LEN(L1114)-1) -> 04889399420 | N1114: =(3000000000000+M1114) -> 3004889399420 | O1114: =(5000000000000+M1114) -> 5004889399420 | P1114: {=N1114 & MOD(10 - MOD(SUMPRODUCT(MID(N1114, ROW(INDIRECT("1:" & LEN(N1114))), 1) * IF(MOD(ROW(INDIRECT("1:" & LEN(N1114))), 2) = 0, 1, 3)), 10), 10)} -> 30048893994205
A1115: 4419124 | B1115: =VLOOKUP(A1115, Sheet1!A:Z, 2, FALSE) -> 2 | C1115: 4 | D1115: {=--_xlfn.TEXTJOIN("",TRUE,IF(ISNUMBER(MID(LEFT(MID(VLOOKUP(A1115,Sheet1!A:Z,12,FALSE),2,99),FIND(")",VLOOKUP(A1115,Sheet1!A:Z,12,FALSE))-2),ROW($1:$20),1)+0),MID(LEFT(MID(VLOOKUP(A1115,Sheet1!A:Z,12,FALSE),2,99),FIND(")",VLOOKUP(A1115,Sheet1!A:Z,12,FALSE))-2),ROW($1:$20),1),""))} -> 2 | E1115: =IF(ISNUMBER(SEARCH("Minimum", VLOOKUP(A1115, Sheet1!A:Z, 12, FALSE))), TRUE, FALSE) -> TRUE | F1115: =QUOTIENT(B1115, C1115) -> 0 | G1115: =VALUE(VLOOKUP(A1115, Sheet1!A:Z, 11, FALSE))>=10 -> TRUE | H1115: =VLOOKUP(A1115, Sheet1!A:Z, 11, FALSE) -> 40.80 | I1115: =VLOOKUP(A1115, Sheet1!A:Z, 13, FALSE) -> 21.60 | J1115: =IF(E1115, I1115, IF(C1115<>D1115,I1115,H1115)) -> 21.60 | K1115: =(J1115+20%)*2.8 -> 61.04 | L1115: =VLOOKUP(A1115, Sheet1!A:Z, 5, FALSE) -> 048893993023 | M1115: =LEFT(L1115, LEN(L1115)-1) -> 04889399302 | N1115: =(3000000000000+M1115) -> 3004889399302 | O1115: =(5000000000000+M1115) -> 5004889399302 | P1115: {=N1115 & MOD(10 - MOD(SUMPRODUCT(MID(N1115, ROW(INDIRECT("1:" & LEN(N1115))), 1) * IF(MOD(ROW(INDIRECT("1:" & LEN(N1115))), 2) = 0, 1, 3)), 10), 10)} -> 30048893993024
A1116: 4421315 | B1116: =VLOOKUP(A1116, Sheet1!A:Z, 2, FALSE) -> 2 | C1116: 2 | D1116: {=--_xlfn.TEXTJOIN("",TRUE,IF(ISNUMBER(MID(LEFT(MID(VLOOKUP(A1116,Sheet1!A:Z,12,FALSE),2,99),FIND(")",VLOOKUP(A1116,Sheet1!A:Z,12,FALSE))-2),ROW($1:$20),1)+0),MID(LEFT(MID(VLOOKUP(A1116,Sheet1!A:Z,12,FALSE),2,99),FIND(")",VLOOKUP(A1116,Sheet1!A:Z,12,FALSE))-2),ROW($1:$20),1),""))} -> 2 | E1116: =IF(ISNUMBER(SEARCH("Minimum", VLOOKUP(A1116, Sheet1!A:Z, 12, FALSE))), TRUE, FALSE) -> FALSE | F1116: =QUOTIENT(B1116, C1116) -> 1 | G1116: =VALUE(VLOOKUP(A1116, Sheet1!A:Z, 11, FALSE))>=10 -> TRUE | H1116: =VLOOKUP(A1116, Sheet1!A:Z, 11, FALSE) -> 44.95 | I1116: =VLOOKUP(A1116, Sheet1!A:Z, 13, FALSE) -> 39.85 | J1116: =IF(E1116, I1116, IF(C1116<>D1116,I1116,H1116)) -> 39.85 | K1116: =(J1116+20%)*2.8 -> 112.14 | L1116: =VLOOKUP(A1116, Sheet1!A:Z, 5, FALSE) -> 048893493615 | M1116: =LEFT(L1116, LEN(L1116)-1) -> 04889349361 | N1116: =(3000000000000+M1116) -> 3004889349361 | O1116: =(5000000000000+M1116) -> 5004889349361 | P1116: {=N1116 & MOD(10 - MOD(SUMPRODUCT(MID(N1116, ROW(INDIRECT("1:" & LEN(N1116))), 1) * IF(MOD(ROW(INDIRECT("1:" & LEN(N1116))), 2) = 0, 1, 3)), 10), 10)} -> 30048893493616
A1117: 4501632 | B1117: =VLOOKUP(A1117, Sheet1!A:Z, 2, FALSE) -> 2 | C1117: 2 | D1117: {=--_xlfn.TEXTJOIN("",TRUE,IF(ISNUMBER(MID(LEFT(MID(VLOOKUP(A1117,Sheet1!A:Z,12,FALSE),2,99),FIND(")",VLOOKUP(A1117,Sheet1!A:Z,12,FALSE))-2),ROW($1:$20),1)+0),MID(LEFT(MID(VLOOKUP(A1117,Sheet1!A:Z,12,FALSE),2,99),FIND(")",VLOOKUP(A1117,Sheet1!A:Z,12,FALSE))-2),ROW($1:$20),1),""))} -> 2 | E1117: =IF(ISNUMBER(SEARCH("Minimum", VLOOKUP(A1117, Sheet1!A:Z, 12, FALSE))), TRUE, FALSE) -> FALSE | F1117: =QUOTIENT(B1117, C1117) -> 1 | G1117: =VALUE(VLOOKUP(A1117, Sheet1!A:Z, 11, FALSE))>=10 -> TRUE | H1117: =VLOOKUP(A1117, Sheet1!A:Z, 11, FALSE) -> 35.55 | I1117: =VLOOKUP(A1117, Sheet1!A:Z, 13, FALSE) -> 30.90 | J1117: =IF(E1117, I1117, IF(C1117<>D1117,I1117,H1117)) -> 30.90 | K1117: =(J1117+20%)*2.8 -> 87.08 | L1117: =VLOOKUP(A1117, Sheet1!A:Z, 5, FALSE) -> 048893447892 | M1117: =LEFT(L1117, LEN(L1117)-1) -> 04889344789 | N1117: =(3000000000000+M1117) -> 3004889344789 | O1117: =(5000000000000+M1117) -> 5004889344789 | P1117: {=N1117 & MOD(10 - MOD(SUMPRODUCT(MID(N1117, ROW(INDIRECT("1:" & LEN(N1117))), 1) * IF(MOD(ROW(INDIRECT("1:" & LEN(N1117))), 2) = 0, 1, 3)), 10), 10)} -> 30048893447893
A1118: 4510447 | B1118: =VLOOKUP(A1118, Sheet1!A:Z, 2, FALSE) -> 2 | C1118: 2 | D1118: {=--_xlfn.TEXTJOIN("",TRUE,IF(ISNUMBER(MID(LEFT(MID(VLOOKUP(A1118,Sheet1!A:Z,12,FALSE),2,99),FIND(")",VLOOKUP(A1118,Sheet1!A:Z,12,FALSE))-2),ROW($1:$20),1)+0),MID(LEFT(MID(VLOOKUP(A1118,Sheet1!A:Z,12,FALSE),2,99),FIND(")",VLOOKUP(A1118,Sheet1!A:Z,12,FALSE))-2),ROW($1:$20),1),""))} -> 2 | E1118: =IF(ISNUMBER(SEARCH("Minimum", VLOOKUP(A1118, Sheet1!A:Z, 12, FALSE))), TRUE, FALSE) -> FALSE | F1118: =QUOTIENT(B1118, C1118) -> 1 | G1118: =VALUE(VLOOKUP(A1118, Sheet1!A:Z, 11, FALSE))>=10 -> TRUE | H1118: =VLOOKUP(A1118, Sheet1!A:Z, 11, FALSE) -> 33.55 | I1118: =VLOOKUP(A1118, Sheet1!A:Z, 13, FALSE) -> 29.70 | J1118: =IF(E1118, I1118, IF(C1118<>D1118,I1118,H1118)) -> 29.70 | K1118: =(J1118+20%)*2.8 -> 83.72 | L1118: =VLOOKUP(A1118, Sheet1!A:Z, 5, FALSE) -> 048893959050 | M1118: =LEFT(L1118, LEN(L1118)-1) -> 04889395905 | N1118: =(3000000000000+M1118) -> 3004889395905 | O1118: =(5000000000000+M1118) -> 5004889395905 | P1118: {=N1118 & MOD(10 - MOD(SUMPRODUCT(MID(N1118, ROW(INDIRECT("1:" & LEN(N1118))), 1) * IF(MOD(ROW(INDIRECT("1:" & LEN(N1118))), 2) = 0, 1, 3)), 10), 10)} -> 30048893959051
